<?xml version="1.0" ?>
<robot name="puz_anchor">
  <link name="base_link">
    <inertial>
      <origin rpy="0.0000 0.0000 0.0000" xyz="0.0000 0.0000 0.0000"/>
      <mass value="0.1"/>
      <inertia ixx="0.01" ixy="0" ixz="0" iyy="0.01" iyz="0" izz="0.01"/>
    </inertial>
  </link>
  <material name="gray">
    <color rgba="0.50 0.50 0.50 0.99"/>
  </material>
  <link name="back_anchor_leg">
    <visual>
      <origin rpy="0.0000 0.0000 0.0000" xyz="0.0000 0.0000 0.0000"/>
      <geometry>
        <box size="0.0020 0.0050 0.0085"/>
      </geometry>
      <material name="gray"/>
    </visual>
    <collision>
      <origin rpy="0.0000 0.0000 0.0000" xyz="0.0000 0.0000 0.0000"/>
      <geometry>
        <box size="0.0020 0.0050 0.0085"/>
      </geometry>
    </collision>
    <inertial>
      <origin rpy="0.0000 0.0000 0.0000" xyz="0.0000 0.0000 0.0000"/>
      <mass value="0.001"/>
      <inertia ixx="8.104166666666667e-09" ixy="0" ixz="0" iyy="6.354166666666667e-09" iyz="0" izz="2.416666666666667e-09"/>
    </inertial>
  </link>
  <joint name="back_anchor_leg_joint" type="fixed">
    <origin rpy="0.0000 0.0000 0.0000" xyz="0.0020 0.0000 0.0000"/>
    <parent link="base_link"/>
    <child link="back_anchor_leg"/>
  </joint>
  <link name="back_anchor_base">
    <visual>
      <origin rpy="0.0000 0.0000 0.0000" xyz="0.0000 0.0000 0.0000"/>
      <geometry>
        <box size="0.0110 0.0020 0.0085"/>
      </geometry>
      <material name="gray"/>
    </visual>
    <collision>
      <origin rpy="0.0000 0.0000 0.0000" xyz="0.0000 0.0000 0.0000"/>
      <geometry>
        <box size="0.0110 0.0020 0.0085"/>
      </geometry>
    </collision>
    <inertial>
      <origin rpy="0.0000 0.0000 0.0000" xyz="0.0000 0.0000 0.0000"/>
      <mass value="0.001"/>
      <inertia ixx="6.354166666666667e-09" ixy="0" ixz="0" iyy="1.6104166666666668e-08" iyz="0" izz="1.0416666666666664e-08"/>
    </inertial>
  </link>
  <joint name="back_anchor_base_joint" type="fixed">
    <origin rpy="0.0000 0.0000 0.0000" xyz="0.0055 0.0000 0.0000"/>
    <parent link="back_anchor_leg"/>
    <child link="back_anchor_base"/>
  </joint>
  <link name="back_anchor_head">
    <visual>
      <origin rpy="0.0000 0.0000 0.0000" xyz="0.0000 0.0000 0.0000"/>
      <geometry>
        <box size="0.0010 0.0055 0.0095"/>
      </geometry>
      <material name="gray"/>
    </visual>
    <collision>
      <origin rpy="0.0000 0.0000 0.0000" xyz="0.0000 0.0000 0.0000"/>
      <geometry>
        <box size="0.0010 0.0055 0.0095"/>
      </geometry>
    </collision>
    <inertial>
      <origin rpy="0.0000 0.0000 0.0000" xyz="0.0000 0.0000 0.0000"/>
      <mass value="0.001"/>
      <inertia ixx="1.0041666666666667e-08" ixy="0" ixz="0" iyy="7.604166666666666e-09" iyz="0" izz="2.604166666666666e-09"/>
    </inertial>
  </link>
  <joint name="back_anchor_head_joint" type="fixed">
    <origin rpy="0.0000 0.0000 0.0000" xyz="0.0055 0.0000 0.0000"/>
    <parent link="back_anchor_base"/>
    <child link="back_anchor_head"/>
  </joint>
  <link name="back_anchor_left">
    <visual>
      <origin rpy="0.0000 0.0000 0.0000" xyz="0.0000 0.0050 0.0000"/>
      <geometry>
        <box size="0.0010 0.0100 0.0095"/>
      </geometry>
      <material name="gray"/>
    </visual>
    <collision>
      <origin rpy="0.0000 0.0000 0.0000" xyz="0.0000 0.0050 0.0000"/>
      <geometry>
        <box size="0.0010 0.0100 0.0095"/>
      </geometry>
    </collision>
    <inertial>
      <origin rpy="0.0000 0.0000 0.0000" xyz="0.0000 0.0050 0.0000"/>
      <mass value="0.001"/>
      <inertia ixx="1.5854166666666666e-08" ixy="0" ixz="0" iyy="7.604166666666666e-09" iyz="0" izz="8.416666666666668e-09"/>
    </inertial>
  </link>
  <joint name="back_anchor_left_joint" type="revolute">
    <origin rpy="0.0000 0.0000 0.3000" xyz="0.0000 0.0027 0.0000"/>
    <parent link="back_anchor_head"/>
    <child link="back_anchor_left"/>
    <axis xyz="0 0 1"/>
    <limit effort="5" lower="-0.3" upper="1.2707963267948965" velocity="2"/>
  </joint>
  <link name="back_anchor_right">
    <visual>
      <origin rpy="0.0000 0.0000 0.0000" xyz="0.0000 -0.0050 0.0000"/>
      <geometry>
        <box size="0.0010 0.0100 0.0095"/>
      </geometry>
      <material name="gray"/>
    </visual>
    <collision>
      <origin rpy="0.0000 0.0000 0.0000" xyz="0.0000 -0.0050 0.0000"/>
      <geometry>
        <box size="0.0010 0.0100 0.0095"/>
      </geometry>
    </collision>
    <inertial>
      <origin rpy="0.0000 0.0000 0.0000" xyz="0.0000 -0.0050 0.0000"/>
      <mass value="0.001"/>
      <inertia ixx="1.5854166666666666e-08" ixy="0" ixz="0" iyy="7.604166666666666e-09" iyz="0" izz="8.416666666666668e-09"/>
    </inertial>
  </link>
  <joint name="back_anchor_right_joint" type="revolute">
    <origin rpy="0.0000 0.0000 -0.3000" xyz="0.0000 -0.0027 0.0000"/>
    <parent link="back_anchor_head"/>
    <child link="back_anchor_right"/>
    <axis xyz="0 0 1"/>
    <limit effort="5" lower="-1.2707963267948965" upper="0.3" velocity="2"/>
  </joint>
  <transmission name="back_anchor_left_transmission" type="SimpleTransmission">
    <type>transmission_interface/SimpleTransmission</type>
    <joint name="back_anchor_left_joint">
      <hardwareInterface>EffortJointInterface</hardwareInterface>
    </joint>
    <actuator name="back_anchor_left_motor">
      <hardwareInterface>EffortJointInterface</hardwareInterface>
      <mechanicalReduction>1</mechanicalReduction>
    </actuator>
  </transmission>
  <transmission name="back_anchor_right_transmission" type="SimpleTransmission">
    <type>transmission_interface/SimpleTransmission</type>
    <joint name="back_anchor_right_joint">
      <hardwareInterface>EffortJointInterface</hardwareInterface>
    </joint>
    <actuator name="back_anchor_right_motor">
      <hardwareInterface>EffortJointInterface</hardwareInterface>
      <mechanicalReduction>1</mechanicalReduction>
    </actuator>
  </transmission>
</robot>
